#VRML_SIM R2023b utf8

EXTERNPROTO "https://raw.githubusercontent.com/cyberbotics/webots/R2023b/projects/objects/backgrounds/protos/TexturedBackground.proto"
EXTERNPROTO "https://raw.githubusercontent.com/cyberbotics/webots/R2023b/projects/objects/backgrounds/protos/TexturedBackgroundLight.proto"
EXTERNPROTO "https://raw.githubusercontent.com/cyberbotics/webots/R2023b/projects/objects/floors/protos/RectangleArena.proto"

WorldInfo {
  info [
    "Example use of a spherical Camera device."
  ]
  title "Spherical Camera"
}
Viewpoint {
  orientation 0.1489899722471261 0.30841150987657423 -0.93951281457224 0.7392673061607542
  position -1.3902159439770259 1.1282925543445559 0.6813839916909735
}
TexturedBackground {
}
TexturedBackgroundLight {
}
RectangleArena {
}
DEF GREEN_OBJECT Solid {
  translation -0.21473646 -0.43026667 0.05
  rotation 0.0026909805133862965 -0.0026909805133862965 -0.9999927585976576 1.5708
  children [
    DEF BOX_SHAPE Shape {
      appearance PBRAppearance {
        baseColor 0 1 0
        roughness 0.2189099510000001
        metalness 0
      }
      geometry Box {
        size 0.1 0.23 0.1
      }
    }
  ]
  name "green object"
  boundingObject USE BOX_SHAPE
}
DEF BLUE_OBJECT Solid {
  translation 0.393343 -0.199452 0.07
  rotation -0.45854819001874086 -0.6283842603974643 -0.6283842603974643 -2.281714
  children [
    DEF SPHERE_SHAPE Shape {
      appearance PBRAppearance {
        baseColor 0 0 1
        roughness 0.519341125
        metalness 0
      }
      geometry Sphere {
        radius 0.07
        subdivision 2
      }
    }
  ]
  name "blue object"
  boundingObject USE SPHERE_SHAPE
}
DEF PINK_OBJECT Solid {
  translation 0.0630102 0.210413 0.05
  rotation 0.7071067811865476 0.7071067811865476 0 3.14159
  children [
    DEF CYLINDER_SHAPE Shape {
      appearance PBRAppearance {
        baseColor 1 0.1 0.3
        roughness 0.16827074099999995
        metalness 0
      }
      geometry Cylinder {
        height 0.1
        radius 0.1
        subdivision 20
      }
    }
  ]
  name "pink object"
  boundingObject USE CYLINDER_SHAPE
}
Robot {
  translation -0.03831630427758424 0.3730111674829703 -0.00022968049685272857
  rotation 0.014324988578023511 0.5013365706445613 -0.8651337686373076 0.056823950245782094
  children [
    Pose {
      translation 0 0 0.0415
      rotation 0 0 1 -1.570796
      children [
        Shape {
          appearance PBRAppearance {
            baseColor 0.74902 0.74902 0.74902
            roughness 1
            metalness 0
          }
          geometry DEF BODY Cylinder {
            height 0.08
            radius 0.045
          }
        }
      ]
    }
    HingeJoint {
      jointParameters HingeJointParameters {
        position 49.57549639297437
        axis 0 1 0
        anchor 0 0 0.025
      }
      device [
        RotationalMotor {
          name "left wheel motor"
          consumptionFactor 70
        }
        PositionSensor {
          name "left wheel sensor"
        }
      ]
      endPoint Solid {
        translation 0 0.045 0.025
        rotation 0.4199897534047077 -0.41998983411361984 -0.804498071020849 1.786637067379393
        children [
          DEF WHEEL Pose {
            rotation 0.577656895078166 0.5771968951617173 -0.5771968951617173 -2.093935
            children [
              Shape {
                appearance PBRAppearance {
                  baseColor 0.301961 0.301961 0.301961
                  roughness 1
                  metalness 0
                }
                geometry Cylinder {
                  height 0.01
                  radius 0.025
                }
              }
            ]
          }
        ]
        name "left wheel"
        boundingObject USE WHEEL
        physics DEF PHYSICS_WHEEL Physics {
          density -1
          mass 0.05
        }
        linearVelocity 0.08147436869131654 -0.004159236239423283 1.6919258548139007e-06
        angularVelocity 0.16529963152513621 3.2446507263754705 0.07775208274943109
      }
    }
    HingeJoint {
      jointParameters HingeJointParameters {
        position 37.588400135412975
        axis 0 1 0
        anchor 0 0 0.025
      }
      device [
        RotationalMotor {
          name "right wheel motor"
          consumptionFactor 70
        }
        PositionSensor {
          name "right wheel sensor"
        }
      ]
      endPoint Solid {
        translation 0 -0.04499999999999999 0.025
        rotation -0.007163210980815139 0.007163215899895289 -0.9999486870566988 1.5708477298313757
        children [
          USE WHEEL
        ]
        name "right wheel"
        boundingObject USE WHEEL
        physics USE PHYSICS_WHEEL
        linearVelocity 0.08835921980360445 -0.0044992230429733585 -1.0401553561931246e-06
        angularVelocity 0.18109930330831203 3.5491524649718116 0.07861385985346214
      }
    }
    DEF US0 DistanceSensor {
      translation 0.042 0.02 0.063
      rotation 0 0 -1 -0.499205
      children [
        DEF SONAR_SENSOR Pose {
          rotation 0.577656895078166 0.5771968951617173 -0.5771968951617173 -2.093935
          children [
            Shape {
              appearance PBRAppearance {
                baseColor 0.301961 0.301961 0.301961
                roughness 1
                metalness 0
              }
              geometry Cylinder {
                height 0.004
                radius 0.008
              }
            }
          ]
        }
      ]
      name "us0"
      lookupTable [
        0 0.7 0
        0.2 0 0
      ]
      type "sonar"
      numberOfRays 20
    }
    DEF US1 DistanceSensor {
      translation 0.042 -0.02 0.063
      rotation 0 0 1 -0.500795
      children [
        USE SONAR_SENSOR
      ]
      name "us1"
      lookupTable [
        0 0.7 0
        0.2 0 0
      ]
      type "sonar"
      numberOfRays 20
    }
    DEF SPHERICAL_CAMERA Camera {
      translation 0 0 0.15
      rotation 0 1 0 1.5708
      children [
        DEF LENS Shape {
          appearance PBRAppearance {
            baseColor 0 0 0
            roughness 1.1102230246251565e-16
            metalness 0
          }
          geometry Sphere {
            radius 0.005
            subdivision 2
          }
        }
        DEF STRUCTURE_AXES Shape {
          appearance Appearance {
            material Material {
              diffuseColor 0.02 0.02 0.02
            }
          }
          geometry IndexedLineSet {
            coord Coordinate {
              point [
                -0.01 0 0
                0.08 -0.01 0
                0.08 0.01 0
                0.08 0 0.01
                0.08 0 -0.01
              ]
            }
            coordIndex [
              0, 1, 0, 2, 0, 3, 0, 4
            ]
          }
        }
        DEF CAMERA_SHAPE Pose {
          translation -0.01 0 0
          rotation 0 1 0 1.5708
          children [
            DEF CAMERA_OUTLINE Shape {
              appearance PBRAppearance {
                baseColor 0.898039 0.898039 0.898039
                roughness 1
                metalness 0
              }
              geometry Cylinder {
                height 0.02
                radius 0.008
              }
            }
          ]
        }
      ]
      fieldOfView 3.1415
      width 128
      height 128
      projection "spherical"
      antiAliasing TRUE
    }
    DEF SMILE Pose {
      translation 0.036 0 0.025
      rotation 0.25056300542381216 -0.9351130202419243 -0.25056300542381216 1.637834
      children [
        Shape {
          appearance PBRAppearance {
            baseColor 0.301961 0.301961 0.301961
            roughness 1
            metalness 0
          }
          geometry Cylinder {
            height 0.018
            radius 0.009
            subdivision 3
          }
        }
      ]
    }
  ]
  name "MyBot"
  boundingObject Pose {
    translation 0 0 0.0415
    rotation 0 0 1 -1.570796
    children [
      USE BODY
    ]
  }
  physics Physics {
    density -1
    mass 0.5
    centerOfMass [
      0 0 0.05
    ]
  }
  controller "spherical_camera"
  linearVelocity 0.08491069903645126 -0.004272027341956252 1.4287871083524167e-05
  angularVelocity -6.273728434208047e-05 0.0003599279401983801 0.07666679837123803
}
