#VRML_SIM R2023b utf8

EXTERNPROTO "https://raw.githubusercontent.com/cyberbotics/webots/R2023b/projects/objects/backgrounds/protos/TexturedBackground.proto"
EXTERNPROTO "https://raw.githubusercontent.com/cyberbotics/webots/R2023b/projects/objects/backgrounds/protos/TexturedBackgroundLight.proto"
EXTERNPROTO "https://raw.githubusercontent.com/cyberbotics/webots/R2023b/projects/objects/floors/protos/RectangleArena.proto"

WorldInfo {
  info [
    "Example use of 'noiseMaskUrl' field of a color Camera device."
  ]
  title "Camera Noise Mask"
}
Viewpoint {
  orientation 0.14557145516175116 0.19129103753321658 -0.9706784691140294 1.8567561087703253
  position 0.4763143752685961 1.205735230208557 0.7029839944799768
}
TexturedBackground {
}
TexturedBackgroundLight {
}
RectangleArena {
}
PointLight {
  attenuation 0 0 1
  intensity 0.6
  location 0 0 0.6
}
DEF GREEN_BOX Solid {
  translation 0.25 0.05 0.05
  children [
    Shape {
      appearance PBRAppearance {
        baseColor 0 1 0
        roughness 0.2189099510000001
        metalness 0
      }
      geometry DEF BOX0 Box {
        size 0.1 0.23 0.1
      }
    }
  ]
  name "green box"
  boundingObject Shape {
    appearance PBRAppearance {
      metalness 0
    }
    geometry USE BOX0
  }
}
DEF BLUE_BOX Solid {
  translation -0.27 -0.2 0.05
  rotation 0 0 1 0.31
  children [
    Shape {
      appearance PBRAppearance {
        baseColor 0 0 1
        roughness 0.519341125
        metalness 0
      }
      geometry DEF BOX1 Box {
        size 0.1 0.2 0.1
      }
    }
  ]
  name "blue box"
  boundingObject Shape {
    appearance PBRAppearance {
      metalness 0
    }
    geometry USE BOX1
  }
}
DEF WHITE_BOX Solid {
  translation -0.15 0.2 0.05
  rotation 0 0 1 0.4
  children [
    Shape {
      appearance PBRAppearance {
        baseColor 0.74902 0.74902 0.74902
        roughness 0.10196099999999997
        metalness 0
      }
      geometry DEF BOX2 Box {
        size 0.3 0.05 0.1
      }
    }
  ]
  name "gray box"
  boundingObject Shape {
    appearance PBRAppearance {
      metalness 0
    }
    geometry USE BOX2
  }
}
DEF RED_BOX Solid {
  translation 0.1 -0.42 0.05
  rotation 0 0 1 1.8326
  children [
    Shape {
      appearance PBRAppearance {
        baseColor 1 0 0
        roughness 0.16827074099999995
        metalness 0
      }
      geometry DEF BOX3 Box {
        size 0.08 0.2 0.1
      }
    }
  ]
  name "red box"
  boundingObject Shape {
    appearance PBRAppearance {
      metalness 0
    }
    geometry USE BOX3
  }
}
Robot {
  translation -0.006227923048891433 -0.1484966541135637 -0.0005202401326346237
  rotation 0.011185934731262588 -0.12610480067312946 -0.9919538568458606 -0.17324334956697474
  children [
    Pose {
      translation 0 0 0.0415
      rotation 0 0 1 -1.570796
      children [
        Shape {
          appearance PBRAppearance {
            baseColor 0.0820075 0.364731 0.8
            roughness 1
            metalness 0
          }
          geometry DEF BODY Cylinder {
            height 0.08
            radius 0.045
          }
        }
      ]
    }
    HingeJoint {
      jointParameters HingeJointParameters {
        position -32.4567857859569
        axis 0 1 0
        anchor 0 0 0.025
      }
      device [
        RotationalMotor {
          name "left wheel motor"
          consumptionFactor 70
        }
        PositionSensor {
          name "left wheel sensor"
        }
      ]
      endPoint Solid {
        translation 0 0.045 0.025
        rotation -0.5210100548564434 0.5210101664673699 0.6760894387402672 4.330588365515777
        children [
          DEF WHEEL Pose {
            rotation 0.577656895078166 0.5771968951617173 -0.5771968951617173 -2.093935
            children [
              Shape {
                appearance PBRAppearance {
                  baseColor 1 0 0
                  roughness 1
                  metalness 0
                }
                geometry Cylinder {
                  height 0.01
                  radius 0.025
                }
              }
            ]
          }
        ]
        name "left wheel"
        boundingObject USE WHEEL
        physics DEF PHYSICS_WHEEL Physics {
          density -1
          mass 0.05
        }
        linearVelocity -0.11297497448969356 -0.01310038460130438 4.1260237352249205e-06
        angularVelocity 0.4815511192382149 -3.97710138600364 2.5691287558967684
      }
    }
    HingeJoint {
      jointParameters HingeJointParameters {
        position 32.45706584657278
        axis 0 1 0
        anchor 0 0 0.025
      }
      device [
        RotationalMotor {
          name "right wheel motor"
          consumptionFactor 70
        }
        PositionSensor {
          name "right wheel sensor"
        }
      ]
      endPoint Solid {
        translation 0 -0.045 0.025
        rotation 0.4823256796692213 -0.4823256409312486 0.7312481896263976 4.404375645822169
        children [
          USE WHEEL
        ]
        name "right wheel"
        boundingObject USE WHEEL
        physics USE PHYSICS_WHEEL
        linearVelocity 0.1127473585330507 0.012909863585497658 5.034505665762045e-06
        angularVelocity -0.48034716777639713 3.9681444018455982 2.568575080982467
      }
    }
    DistanceSensor {
      translation 0.042 0.02 0.063
      rotation 0 0 -1 -0.499205
      children [
        DEF SENSOR Pose {
          rotation 0.577656895078166 0.5771968951617173 -0.5771968951617173 -2.093935
          children [
            Shape {
              appearance PBRAppearance {
                baseColor 0.975691 0.981481 0.0252992
                roughness 1
                metalness 0
              }
              geometry Cylinder {
                height 0.004
                radius 0.008
              }
            }
          ]
        }
      ]
      name "ds0"
      lookupTable [
        0 1024 0
        0.05 1024 0
        0.15 0 0
      ]
      numberOfRays 2
      aperture 1
    }
    DistanceSensor {
      translation 0.042 -0.02 0.063
      rotation 0 0 1 -0.500795
      children [
        USE SENSOR
      ]
      name "ds1"
      lookupTable [
        0 1024 0
        0.05 1024 0
        0.15 0 0
      ]
      numberOfRays 2
      aperture 1
    }
    DEF SMILE Pose {
      translation 0.036 0 0.025
      rotation 0.25056300542381216 -0.9351130202419243 -0.25056300542381216 1.637834
      children [
        Shape {
          appearance PBRAppearance {
            baseColor 0.721569 0.290196 0.290196
            roughness 1
            metalness 0
          }
          geometry Cylinder {
            height 0.018
            radius 0.009
            subdivision 3
          }
        }
      ]
    }
    Camera {
      translation 0.04 0 0.0915
      children [
        Pose {
          translation -0.015 0 0
          rotation -0.5771968951617173 -0.577656895078166 -0.5771968951617173 -2.093935
          children [
            Shape {
              appearance PBRAppearance {
                roughness 1
                metalness 0
              }
              geometry Cylinder {
                height 0.03
                radius 0.01
              }
            }
          ]
        }
      ]
      fieldOfView 1.047
      width 400
      height 300
      antiAliasing TRUE
      noiseMaskUrl "https://raw.githubusercontent.com/cyberbotics/webots/R2023b/projects/samples/devices/worlds/textures/noise_mask.png"
    }
  ]
  name "MyBot"
  boundingObject Pose {
    translation 0 0 0.0415
    rotation 0 0 1 -1.570796
    children [
      USE BODY
    ]
  }
  physics Physics {
    density -1
    mass 0.5
  }
  controller "camera"
  linearVelocity -0.00030617579279411465 0.000801127314889668 -0.0002014881255327061
  angularVelocity 0.0007141294930205241 -0.004472337247396532 2.498947514877311
}
