#VRML_SIM R2023b utf8

EXTERNPROTO "https://raw.githubusercontent.com/cyberbotics/webots/R2023b/projects/objects/backgrounds/protos/TexturedBackground.proto"
EXTERNPROTO "https://raw.githubusercontent.com/cyberbotics/webots/R2023b/projects/objects/backgrounds/protos/TexturedBackgroundLight.proto"
EXTERNPROTO "https://raw.githubusercontent.com/cyberbotics/webots/R2023b/projects/objects/floors/protos/RectangleArena.proto"
EXTERNPROTO "https://raw.githubusercontent.com/cyberbotics/webots/R2023b/projects/objects/drinks/protos/Can.proto"
EXTERNPROTO "https://raw.githubusercontent.com/cyberbotics/webots/R2023b/projects/objects/fruits/protos/Apple.proto"
EXTERNPROTO "https://raw.githubusercontent.com/cyberbotics/webots/R2023b/projects/objects/school_furniture/protos/Book.proto"
EXTERNPROTO "https://raw.githubusercontent.com/cyberbotics/webots/R2023b/projects/objects/obstacles/protos/OilBarrel.proto"
EXTERNPROTO "https://raw.githubusercontent.com/cyberbotics/webots/R2023b/projects/objects/balls/protos/SoccerBall.proto"

WorldInfo {
  info [
    "Example use of a color Camera device with auto-focusing capabilities."
  ]
  title "Camera With Auto-Focus"
}
Viewpoint {
  orientation -0.266198791418952 0.11678027290007822 0.9568179405239393 2.2715624501233096
  position 0.39754188166782156 -0.6892520235424072 0.6503573755209902
}
TexturedBackground {
}
TexturedBackgroundLight {
}
RectangleArena {
  floorTileSize 0.25 0.25
  wallHeight 0.15
  wallAppearance PBRAppearance {
    baseColorMap ImageTexture {
      url [
        "https://raw.githubusercontent.com/cyberbotics/webots/R2023b/projects/default/worlds/textures/red_brick_wall.jpg"
      ]
    }
    roughness 1
    metalness 0
    textureTransform TextureTransform {
      scale 6 7
    }
  }
}
Robot {
  translation -0.002837632432674569 0.007119251010753896 -0.0002285648913921967
  rotation 0.014214482396770582 0.0008593070825932399 -0.9998985998997746 3.0208226485969787
  children [
    Pose {
      translation 0 0 0.0415
      rotation 0 0 1 -1.570796
      children [
        Shape {
          appearance PBRAppearance {
            baseColor 0.0820075 0.364731 0.8
            roughness 1
            metalness 0
          }
          geometry DEF BODY Cylinder {
            height 0.08
            radius 0.045
          }
        }
      ]
    }
    HingeJoint {
      jointParameters HingeJointParameters {
        position -10.78306409822208
        axis 0 1 0
        anchor 0 0 0.025
      }
      device [
        RotationalMotor {
          name "left wheel motor"
          consumptionFactor 70
        }
        PositionSensor {
          name "left wheel sensor"
        }
      ]
      endPoint Solid {
        translation 0 0.04499999999999999 0.025
        rotation -0.5654991488748932 0.5654993176325681 -0.6003509260248301 2.060237464987464
        children [
          DEF WHEEL Pose {
            rotation 0.577656895078166 0.5771968951617173 -0.5771968951617173 -2.093935
            children [
              Shape {
                appearance PBRAppearance {
                  baseColor 1 0 0
                  roughness 1
                  metalness 0
                }
                geometry Cylinder {
                  height 0.01
                  radius 0.025
                }
              }
            ]
          }
        ]
        name "left wheel"
        boundingObject USE WHEEL
        physics DEF PHYSICS_WHEEL Physics {
          density -1
          mass 0.05
        }
        linearVelocity 0.02239581519214186 0.0025400714404939244 3.153920793855893e-08
        angularVelocity -0.1123374786539147 0.9936958470180758 0.5018393917227436
      }
    }
    HingeJoint {
      jointParameters HingeJointParameters {
        position 10.783049385790237
        axis 0 1 0
        anchor 0 0 0.025
      }
      device [
        RotationalMotor {
          name "right wheel motor"
          consumptionFactor 70
        }
        PositionSensor {
          name "right wheel sensor"
        }
      ]
      endPoint Solid {
        translation 0 -0.04499999999999999 0.025
        rotation 0.5934647919053144 -0.5934647362229162 -0.5436903048874848 2.1456206989503634
        children [
          USE WHEEL
        ]
        name "right wheel"
        boundingObject USE WHEEL
        physics USE PHYSICS_WHEEL
        linearVelocity -0.022396546344800764 -0.002539407848417585 5.5545121782216683e-08
        angularVelocity 0.11233914131880318 -0.9937053851947626 0.5018400728433293
      }
    }
    DistanceSensor {
      translation 0.04 0 0.0915
      lookupTable [
        0 0 0
        1 1000 0
      ]
    }
    DEF SMILE Pose {
      translation 0.036 0 0.025
      rotation 0.25056300542381216 -0.9351130202419243 -0.25056300542381216 1.637834
      children [
        Shape {
          appearance PBRAppearance {
            baseColor 0.721569 0.290196 0.290196
            roughness 1
            metalness 0
          }
          geometry Cylinder {
            height 0.018
            radius 0.009
            subdivision 3
          }
        }
      ]
    }
    Camera {
      translation 0.04 0 0.0915
      children [
        Pose {
          translation -0.015 0 0
          rotation -0.5771968951617173 -0.577656895078166 -0.5771968951617173 -2.093935
          children [
            Shape {
              appearance PBRAppearance {
                roughness 1
                metalness 0
              }
              geometry Cylinder {
                height 0.03
                radius 0.01
              }
            }
          ]
        }
      ]
      fieldOfView 1
      width 400
      height 300
      focus Focus {
        focalDistance 0.18714149553492987
        focalLength 0.25
        maxFocalDistance 1
        minFocalDistance 0.1
      }
    }
    DEF RIGHT_EYE Pose {
      translation 0.042 0.02 0.063
      rotation 0.3871000691202075 0.6519791164167495 0.6519791164167495 2.40292
      children [
        Shape {
          appearance PBRAppearance {
            baseColor 0.975691 0.981481 0.0252992
            roughness 1
            metalness 0
          }
          geometry Cylinder {
            height 0.004
            radius 0.008
          }
        }
      ]
    }
    DEF LEFT_EYE Pose {
      translation 0.042 -0.02 0.063
      rotation 0.7664071928227091 0.45421311427685446 0.45421411427710606 1.83375
      children [
        Shape {
          appearance PBRAppearance {
            baseColor 0.975691 0.981481 0.0252992
            roughness 1
            metalness 0
          }
          geometry Cylinder {
            height 0.004
            radius 0.008
          }
        }
      ]
    }
  ]
  name "MyBot"
  boundingObject Pose {
    translation 0 0 0.0415
    rotation 0 0 1 -1.570796
    children [
      USE BODY
    ]
  }
  physics Physics {
    density -1
    mass 0.5
  }
  controller "camera_auto_focus"
  linearVelocity 2.5843970880330642e-05 -0.00023312530994364208 5.1601742825788856e-08
  angularVelocity 8.323348529740128e-07 -4.763580175510789e-06 0.5005903325316106
}
Can {
  translation 0.28 1.6163437824185985e-19 0.06096171086093549
  rotation 3.3266256689820176e-17 -1.26456802543123e-17 1 -3.1415849999999996
}
Apple {
  translation -0.26 0 0.049764791394518226
}
Book {
  translation -0.08660299999999999 -0.29 0.09988239614048448
  rotation 3.446857946835864e-17 -2.934637512024818e-17 1 2.3562
}
OilBarrel {
  translation 0.143119 -0.169397 0.075
  rotation 0 0 1 1.5708
  height 0.2
  radius 0.05
}
SoccerBall {
  translation 0 0.29 0.11205723158604528
}
